Workbook
Name 合併CODE: 對照!$L:$R

Sheet CE店別員別店質List
A3: 計數 - Sold-to
A4: Sold-to | B4: 合併Sold to | C4: 合併Sold Name | D4: 店質 | E4: 業務員 | F4: 業務員部門 | G4: 合計
A5: TW010117A1 | B5: TW010117A1 | C5: 金長益電器 | D5: DC店 | E5: 褚家鳴 | F5: 桃竹營銷處 | G5: 3
A6: TW010157A1 | B6: TW010157A1 | C6: 百鈴電器 | D6: 一般店 | E6: 粘棋欽 | F6: 嘉南營銷處 | G6: 1
A7: TW010274A1 | B7: TW010274A1 | C7: 全省電器 | D7: 專售店 | E7: 歐俊賢 | F7: 嘉南營銷處 | G7: 4
A8: TW010291A1 | B8: TW010291A1 | C8: 聯鈦冷凍空調電器行 | D8: DC店 | E8: 黃坤鎮 | F8: 嘉南營銷處 | G8: 2
A9: TW010303A1 | B9: TW010303A1 | C9: 明聳企業 | D9: 一般店 | E9: 吳章瑋 | F9: AC Team | G9: 1
A10: TW010429A1 | B10: TW010429A1 | C10: 金亞實業 | D10: 專售店 | E10: 錢亮均 | F10: 台北營銷處 | G10: 4
A11: TW010431A1 | B11: TW010431A1 | C11: 萬豐視聽 | D11: DC店 | E11: 錢亮均 | F11: 台北營銷處 | G11: 2
A12: TW010435A1 | B12: TW010435A1 | C12: 上順電器 | D12: 一般店 | E12: 錢亮均 | F12: 台北營銷處 | G12: 2
A13: TW010437A1 | B13: TW010437A1 | C13: 今漢 | D13: 專售店 | E13: 錢亮均 | F13: 台北營銷處 | G13: 4
A14: TW010455A1 | B14: TW010455A1 | C14: 昇廣電器 | D14: 一般店 | E14: 陳慶全 | F14: 台中營銷處 | G14: 1
A15: TW010457A1 | B15: TW010457A1 | C15: 錦穗實業 | D15: 一般店 | E15: 歐俊賢 | F15: 嘉南營銷處 | G15: 1
A16: TW010458A1 | B16: TW010458A1 | C16: 大時代量販 | D16: DC店 | E16: 江柏慶 | F16: 嘉南營銷處 | G16: 1
... A704: TW019319A1 | B704: TW019319A1 | C704: 泰安電器生活館 | D704: 一般店 | E704: 褚家鳴 | F704: 桃竹營銷處 | G704: 3
A705: TW019320A1 | B705: TW019320A1 | C705: 思納捷科技 | E705: 陳崴 | F705: AC Team | G705: 1
A706: 總計 | G706: 1499

Sheet Ship to
A1: 業務員 | B1: 業務員部門 | C1: 店質 | D1: 特殊 | E1: 合併Sold to | F1: 合併Sold Name | G1: Sales Department | H1: Sales Channel Name | I1: Pricing Group Name | J1: Business Area | K1: Legal Entity Code | L1: Legal Entity Name | M1: Sold-to | N1: Sold-to Name | O1: Ship To Code | P1: Ship To Name (Local) | Q1: Ship-to Type | R1: Default (Sales Only) | S1: Store No | T1: Inactive Flag | U1: Ship Group | V1: Ship Group Name | W1: Ship Group Default | X1: Carrier | Y1: TAX Ship-to Code | Z1: Business Registration No | AA1: Region | AB1: Region Description | AC1: Province | AD1: County | AE1: Postal Code | AF1: City | AG1: Street 1 | AH1: Street 2 | AI1: Street 3 | AJ1: Street 4 | AK1: Country | AL1: Contact Person Name | AM1: Contact Person's Mobile | AN1: Usage | AO1: Environmental Fee Flag | AP1: Same Address Code | AQ1: Created On | AR1: Created By | AS1: Changed On | AT1: Changed By | AU1: Company | AV1: Sales Organization | AW1: Distr. Channel | AX1: Created On
A2: 林建宏 | B2: MMCS | C2: 萬家福 | E2: TW012801A1 | F2: 康達盛通生活事業 | G2: MM Part | H2: 萬家福 | I2: 萬家福 | J2: SAL | K2: TW01280100 | L2: 家福股份有限公司總公司-IT | M2: TW012801A1 | N2: 康達盛通生活事業 | O2: TWSG000718 | P2: 三民家福 | Q2: S | S2: MM000101 | X2: TW012676 | Z2: 2794080* | AE2: 105 | AG2: 台北市松山區三民路160號 | AK2: TW | AL2: 陳政道 | AN2: D | AO2: X | AQ2: 2025.11.25 14:58:30 | AR2: 정한석 hanseok.jung@lgepartner.com | AS2: 2026.08.06 10:15:22 | AT2: 노용훈 yonghoon1.noh@lgepartner.com | AU2: EATT | AV2: [LGETT] Common | AW2: Domestic | AX2: 45986
A3: 陳志豐 | B3: 高屏營銷處 | C3: DC店 | E3: TW219300A1 | F3: 弘昇電器行 | G3: AC Team | H3: AC TEAM | I3: DC店 | J3: SAL | K3: TW21930000 | L3: 弘昇電器行 | M3: TW219300A1 | N3: 弘昇電器行 | O3: TWSG001536 | P3: 弘昇電器行(倉庫) | Q3: S | S3: DL003829-S | X3: TW012676 | Z3: 8102123* | AE3: 832 | AG3: 高雄市林園區溪州里溪州二路115巷92號 | AK3: TW | AL3: 謝文弘 | AN3: D | AO3: X | AQ3: 2025.11.25 14:58:35 | AR3: 정한석 hanseok.jung@lgepartner.com | AS3: 2026.07.27 13:15:16 | AT3: PinFang Wang sarah.wang@lge.com | AU3: EATT | AV3: [LGETT] Common | AW3: Domestic | AX3: 45986
A4: #N/A | B4: #N/A | E4: TW219128A1 | F4: ONE TIME SERVICE FOR TYPE 3 | G4: Tech Support Part | H4: SVC | J4: SAL | K4: TW21912800 | L4: ONE TIME SERVICE FOR TYPE 3 | M4: TW219128A1 | N4: ONE TIME SERVICE FOR TYPE 3 | O4: TWSG003597 | P4: One time_SVC AC | Q4: B | X4: TW012676 | AE4: 114 | AG4: 台北市內湖區基湖路3巷47號6樓 | AK4: TW | AL4: * | AN4: M | AO4: X | AQ4: 2026.04.21 16:42:32 | AR4: 김승윤 seungyun2.kim@lgepartner.com | AS4: 2026.06.26 21:32:43 | AT4: 노용훈 yonghoon1.noh@lgepartner.com | AU4: EATT | AV4: [LGETT] Common | AW4: Domestic | AX4: 46133
A5: 沈勇良 | B5: 高屏營銷處 | C5: 一般店 | E5: TW219645A1 | F5: 源洲工程有限公司 | G5: Dealer Sales_KaoPing Team | H5: 高屏營銷處 | I5: 一般店 | J5: SAL | K5: TW21964500 | L5: 源洲工程有限公司 | M5: TW219645A1 | N5: 源洲工程有限公司 | O5: TWSG002905 | P5: 源洲工程有限公司 | Q5: S | R5: Y | S5: TW007855-S | X5: TW012676 | Z5: 4279184* | AE5: 814 | AG5: 高雄市仁武區埤內巷17號 | AK5: TW | AL5: 邱淵豐 | AN5: M | AO5: X | AQ5: 2025.11.25 14:58:36 | AR5: 정한석 hanseok.jung@lgepartner.com | AS5: 2026.06.26 20:03:29 | AT5: 노용훈 yonghoon1.noh@lgepartner.com | AU5: EATT | AV5: [LGETT] Common | AW5: Domestic | AX5: 45986
A6: 陳俊宏 | B6: 百貨 | C6: 百貨 | E6: TW014445A1 | F6: 集雅社 | G6: Department Store Team | H6: 百貨 | I6: 百貨 | J6: SAL | K6: TW01444500 | L6: 集雅社股份有限公司 | M6: TW014445A1 | N6: 集雅社 | O6: TWSG001258 | P6: 集雅社-新北-汐止遠雄 | Q6: S | S6: DL003621-S | X6: TW012676 | Z6: 8926617* | AE6: 221 | AG6: 新北市汐止區新台五路一段93-99號1樓 | AK6: TW | AL6: * | AN6: D | AO6: X | AQ6: 2025.11.25 14:58:36 | AR6: 정한석 hanseok.jung@lgepartner.com | AS6: 2026.06.26 20:03:39 | AT6: 노용훈 yonghoon1.noh@lgepartner.com | AU6: EATT | AV6: [LGETT] Common | AW6: Domestic | AX6: 45986
A7: 黃宗平 | B7: IT Part | C7: IT | E7: TW219603A1 | F7: 集雅社 | G7: LGETT | H7: IT | I7: IT | J7: SAL | K7: TW01444500 | L7: 集雅社股份有限公司 | M7: TW219603A1 | N7: 集雅社 | O7: TWSG003259 | P7: 集雅社-宜蘭-新月廣場 | Q7: S | S7: IT001234-S | X7: TW012676 | Z7: 8926617* | AE7: 260 | AG7: 宜蘭縣宜蘭市民權路二段38巷6號3樓 | AK7: TW | AL7: * 李念慈 | AN7: D | AO7: X | AQ7: 2025.11.25 14:58:40 | AR7: 정한석 hanseok.jung@lgepartner.com | AS7: 2026.06.26 20:21:34 | AT7: 노용훈 yonghoon1.noh@lgepartner.com | AU7: EATT | AV7: [LGETT] Common | AW7: Domestic | AX7: 45986
A8: 陳崴 | B8: AC Team | C8: 一般店 | E8: TW019123A1 | F8: 沅新空調 | G8: LGETT | H8: AC TEAM | I8: 一般店 | J8: SAL | K8: TW01912300 | L8: 沅新空調 | M8: TW019123A1 | N8: 沅新空調 | O8: TWSG003185 | P8: 沅新空調 | Q8: S | R8: Y | S8: TW007869-S | X8: TW012676 | Z8: 2497963* | AE8: 831 | AG8: 高雄市大寮區打鐵店街26巷173-3號 | AK8: TW | AL8: 郭力榮 | AM8: 0935853661 | AN8: M | AO8: X | AQ8: 2025.11.25 14:58:23 | AR8: 정한석 hanseok.jung@lgepartner.com | AS8: 2026.06.26 20:27:37 | AT8: 노용훈 yonghoon1.noh@lgepartner.com | AU8: EATT | AV8: [LGETT] Common | AW8: Domestic | AX8: 45986
A9: 陳昱宏 | B9: MMCS | C9: 大同 | E9: TW018199A1 | F9: 大同綜合訊電(股) | G9: CS Part | H9: 大同 | I9: 大同 | J9: SAL | K9: TW01819900 | L9: 大同綜合訊電股份有限公司 | M9: TW018199A1 | N9: 大同綜合訊電(股) | O9: TWSG002209 | P9: 1130汐止大同大同 | Q9: S | S9: 1130T | X9: TW012676 | Z9: 7078852* | AE9: 221 | AG9: 台北縣汐止市大同路二段497號 | AK9: TW | AL9: * | AN9: D | AO9: X | AQ9: 2025.11.25 14:58:42 | AR9: 정한석 hanseok.jung@lgepartner.com | AS9: 2026.06.26 20:32:59 | AT9: 노용훈 yonghoon1.noh@lgepartner.com | AU9: EATT | AV9: [LGETT] Common | AW9: Domestic | AX9: 45986
A10: 郭本威 | B10: OBS | C10: OBS | E10: TW015380A1 | F10: 康迅數位整合股份有限公司 | G10: OBS Team | H10: OBS | I10: OBS | J10: SAL | K10: TW01538000 | L10: 康迅數位整合股份有限公司 | M10: TW015380A1 | N10: 康迅數位整合股份有限公司 | O10: TWSG003129 | P10: ONE TIME OBS(D2B2C_PAYEASY OMV) | Q10: S | S10: DL004338-S | X10: TW012676 | Z10: 7055321* | AG10: * | AK10: TW | AL10: * | AN10: M | AO10: X | AQ10: 2025.11.25 14:58:38 | AR10: 정한석 hanseok.jung@lgepartner.com | AS10: 2026.06.26 21:00:04 | AT10: 노용훈 yonghoon1.noh@lgepartner.com | AU10: EATT | AV10: [LGETT] Common | AW10: Domestic | AX10: 45986
A11: 蔣承孝 | B11: 高屏營銷處 | C11: 專售店 | E11: TW219187A1 | F11: 棋杰電器行 | G11: Dealer Sales_KaoPing Team | H11: 高屏營銷處 | I11: 專售店 | J11: SAL | K11: TW21918700 | L11: 棋杰電器 | M11: TW219187A1 | N11: 棋杰電器 | O11: TWSG000317 | P11: 棋杰電器行(東源倉) | Q11: S | S11: DL004009-S | X11: TW012676 | Z11: 0801687* | AE11: 821 | AG11: 高雄市路竹區民族路132號 | AK11: TW | AL11: 棋杰電器行(東源倉) | AN11: D | AO11: X | AQ11: 2025.11.25 14:58:23 | AR11: 정한석 hanseok.jung@lgepartner.com | AS11: 2026.06.26 21:00:58 | AT11: 노용훈 yonghoon1.noh@lgepartner.com | AU11: EATT | AV11: [LGETT] Common | AW11: Domestic | AX11: 45986
A12: #N/A | B12: #N/A | C12: B2B2C | E12: TW019190A1 | F12: 匯聚科技 | G12: B2B2C Sales Part | H12: B2B2C(B2B2C Part) | I12: B2B2C | J12: SAL | K12: TW01919000 | L12: 匯聚科技 | M12: TW019190A1 | N12: 匯聚科技 | O12: TWSG003436 | P12: 匯聚科技 | Q12: S | R12: Y | S12: TW007901-S | X12: TW012676 | Z12: 2786858* | AE12: 241 | AG12: 新北市三重區重新路5段646之1號 | AK12: TW | AL12: 吳宛蓁 | AM12: 0970-779796 | AN12: M | AO12: X | AQ12: 2025.11.25 14:58:29 | AR12: 정한석 hanseok.jung@lgepartner.com | AS12: 2026.06.26 21:06:49 | AT12: 노용훈 yonghoon1.noh@lgepartner.com | AU12: EATT | AV12: [LGETT] Common | AW12: Domestic | AX12: 45986
A13: 施漢鵬 | B13: MMCS | C13: 富山淨水 | E13: TW019125A1 | F13: 富山淨水 | G13: MM Part | H13: 富山淨水 | I13: 富山淨水 | J13: SAL | K13: TW01912500 | L13: 富山淨水 | M13: TW019125A1 | N13: 富山淨水 | O13: TWSG003186 | P13: 富山淨水 | Q13: S | R13: Y | S13: TW007871-S | X13: TW012676 | Z13: 2770281* | AE13: 813 | AG13: 高雄市左營區新上里明誠二路515號1樓 | AK13: TW | AL13: 劉崇睿 | AM13: 0931-921-751 | AN13: M | AO13: X | AQ13: 2025.11.25 14:58:26 | AR13: 정한석 hanseok.jung@lgepartner.com | AS13: 2026.06.26 21:06:49 | AT13: 노용훈 yonghoon1.noh@lgepartner.com | AU13: EATT | AV13: [LGETT] Common | AW13: Domestic | AX13: 45986
A14: #N/A | B14: #N/A | E14: TW219139A1 | F14: ONE TIME CUSTOMER | G14: LGETT | H14: ETC | J14: SAL | K14: TW21913900 | L14: ONE TIME CUSTOMER | M14: TW219139A1 | N14: ONE TIME CUSTOMER | O14: TWSG000147 | P14: ONE TIME CUSTOMER | Q14: S | R14: Y | S14: TW006241 | X14: TW012676 | Z14: * | AE14: 114 | AG14: 台北市內湖區基湖路3巷47號7樓 | AK14: TW | AL14: 0 | AN14: D | AO14: X | AQ14: 2025.11.25 14:58:36 | AR14: 정한석 hanseok.jung@lgepartner.com | AS14: 2026.06.26 21:09:56 | AT14: 노용훈 yonghoon1.noh@lgepartner.com | AU14: EATT | AV14: [LGETT] Common | AW14: Domestic | AX14: 45986
A15: 葉作仁 | B15: 桃竹營銷處 | C15: 一般店 | E15: TW219384A1 | F15: 天籟企業社 | G15: Dealer Sales_TaoChu Team | H15: 桃竹營銷處 | I15: 一般店 | J15: SAL | K15: TW21938400 | L15: 天籟企業社 | M15: TW219384A1 | N15: 天籟企業社 | O15: TWSG000747 | P15: 天籟企業社 | Q15: S | S15: TW007296 | X15: TW012676 | Z15: 4996773* | AE15: 320 | AG15: 桃園市楊梅區大華街27號 | AK15: TW | AL15: * 李秀民 | AN15: D | AO15: X | AQ15: 2025.11.25 14:58:36 | AR15: 정한석 hanseok.jung@lgepartner.com | AS15: 2026.06.26 21:15:02 | AT15: 노용훈 yonghoon1.noh@lgepartner.com | AU15: EATT | AV15: [LGETT] Common | AW15: Domestic | AX15: 45986
A16: 吳睿涵 | B16: E-Commerce | C16: ONLINE | E16: TW219605A1 | F16: 富基電通 | G16: E-Commerce Team | H16: ONLINE | I16: ONLINE | J16: SAL | K16: TW01370200 | L16: 富基電通股份有限公司 | M16: TW219605A1 | N16: 富基電通 | O16: TWSG000692 | P16: 富基電通(大園倉庫) | Q16: S | S16: DL003971-S | X16: TW012676 | Z16: 2752554* | AE16: 337 | AG16: 桃園市大園區開和路2號 | AK16: TW | AL16: 莊詩弘 | AN16: D | AO16: X | AQ16: 2025.11.25 14:58:37 | AR16: 정한석 hanseok.jung@lgepartner.com | AS16: 2026.06.26 21:58:50 | AT16: 노용훈 yonghoon1.noh@lgepartner.com | AU16: EATT | AV16: [LGETT] Common | AW16: Domestic | AX16: 45986
A17: 葉日崧 | B17: MMCS | C17: 全國 | E17: TW014442A1 | F17: 全國電子 | G17: CS Part | H17: 全國 | I17: 全國 | J17: SAL | K17: TW01444200 | L17: 全國電子股份有限公司 | M17: TW014442A1 | N17: 全國電子 | O17: TWSG003406 | P17: 3083全國電子(湳雅) | Q17: S | S17: CS001619-S | X17: TW012676 | Z17: 2200625* | AE17: 300 | AG17: 新竹市湳雅街89號1樓 | AK17: TW | AL17: * | AN17: D | AO17: X | AQ17: 2025.11.25 14:58:36 | AR17: 정한석 hanseok.jung@lgepartner.com | AS17: 2026.06.26 19:49:51 | AT17: 노용훈 yonghoon1.noh@lgepartner.com | AU17: EATT | AV17: [LGETT] Common | AW17: Domestic | AX17: 45986
A18: 林宜慧 | B18: E-Commerce | C18: ONLINE | E18: TW219378A1 | F18: 爆器顧問股份有限公司 | G18: E-Commerce Team | H18: ONLINE | I18: ONLINE | J18: SAL | K18: TW21937800 | L18: 爆器顧問股份有限公司 | M18: TW219378A1 | N18: 爆器顧問股份有限公司 | O18: TWSG000208 | P18: 爆器顧問股份有限公司 | Q18: S | R18: Y | S18: TW007290-S | X18: TW012676 | Z18: 8507710* | AE18: 236 | AG18: 新北市土城區裕生路８６巷１２號３樓 | AK18: TW | AL18: 林書弘 | AM18: 0933088894 | AN18: D | AO18: X | AQ18: 2025.11.25 14:58:34 | AR18: 정한석 hanseok.jung@lgepartner.com | AS18: 2026.06.26 19:49:58 | AT18: 노용훈 yonghoon1.noh@lgepartner.com | AU18: EATT | AV18: [LGETT] Common | AW18: Domestic | AX18: 45986
A19: 黃坤鎮 | B19: 嘉南營銷處 | C19: DC店 | E19: TW018827A1 | F19: 中美電器行 | G19: Dealer Sales_ChiaNan Team | H19: 嘉南營銷處 | I19: DC店 | J19: SAL | K19: TW01882700 | L19: 中美電器行 | M19: TW018827A1 | N19: 中美電器行 | O19: TWSG002168 | P19: 中美電器行(莿桐倉) | Q19: S | S19: DL004221-S | X19: TW012676 | Z19: 9282483* | AE19: 647 | AG19: 雲林縣莿桐鄉埔尾村油車路31-1號 | AK19: TW | AL19: * | AN19: D | AO19: X | AQ19: 2025.11.25 14:58:42 | AR19: 정한석 hanseok.jung@lgepartner.com | AS19: 2026.06.26 19:50:03 | AT19: 노용훈 yonghoon1.noh@lgepartner.com | AU19: EATT | AV19: [LGETT] Common | AW19: Domestic | AX19: 45986
A20: 林宜慧 | B20: E-Commerce | C20: ONLINE | E20: TW016899A1 | F20: 包昇股份有限公司 | G20: E-Commerce Team | H20: ONLINE | I20: ONLINE | J20: SAL | K20: TW01689900 | L20: 包昇數位文化有限公司 | M20: TW016899A1 | N20: 包昇股份有限公司 | O20: TWSG000895 | P20: 包昇數位(特捷倉) | Q20: S | S20: DL003669-S | X20: TW012676 | Z20: 5312315* | AE20: 224 | AG20: 新北市瑞芳區楓仔瀨路1巷1號A1棟 | AK20: TW | AL20: 渠淑惠 | AN20: D | AO20: X | AQ20: 2025.11.25 14:58:43 | AR20: 정한석 hanseok.jung@lgepartner.com | AS20: 2026.06.26 19:50:14 | AT20: 노용훈 yonghoon1.noh@lgepartner.com | AU20: EATT | AV20: [LGETT] Common | AW20: Domestic | AX20: 45986
A21: 連承剛 | B21: 百貨 | C21: 百貨 | E21: TW011485A1 | F21: 秀翔 | G21: Department Store Team | H21: 百貨 | I21: 百貨 | J21: SAL | K21: TW01148500 | L21: 秀翔實業有限公司 | M21: TW011485A1 | N21: 秀翔 | O21: TWSG001052 | P21: 秀翔-高雄-新光三越-三多 | Q21: S | S21: DL004442 | X21: TW012676 | Z21: 8942969* | AE21: 806 | AG21: 高雄市前鎮區三多三路213號10樓 | AK21: TW | AL21: 潘玉慧 歐怡玲 | AM21: 09108006080921976013 | AN21: D | AO21: X | AQ21: 2025.11.25 14:58:43 | AR21: 정한석 hanseok.jung@lgepartner.com | AS21: 2026.06.26 19:50:18 | AT21: 노용훈 yonghoon1.noh@lgepartner.com | AU21: EATT | AV21: [LGETT] Common | AW21: Domestic | AX21: 45986
A22: 陳志豐 | B22: 高屏營銷處 | C22: 一般店 | E22: TW219379A1 | F22: 雲彩企業社 | G22: Dealer Sales_KaoPing Team | H22: 高屏營銷處 | I22: 一般店 | J22: SAL | K22: TW21937900 | L22: 雲彩企業社 | M22: TW219379A1 | N22: 雲彩企業社 | O22: TWSG000746 | P22: 雲彩企業社 | Q22: S | R22: Y | S22: TW007291-S | X22: TW012676 | Z22: 8876381* | AE22: 920 | AG22: 屏東縣潮州鎮三共里朝昇路４１號１樓 | AK22: TW | AL22: 賴財正 | AM22: 0921-581-550 | AN22: D | AO22: X | AQ22: 2025.11.25 14:58:36 | AR22: 정한석 hanseok.jung@lgepartner.com | AS22: 2026.06.26 20:01:52 | AT22: 노용훈 yonghoon1.noh@lgepartner.com | AU22: EATT | AV22: [LGETT] Common | AW22: Domestic | AX22: 45986
A23: 陳俊芳 | B23: MMCS | C23: 燦坤 | E23: TW014426A1 | F23: 燦坤 | G23: CS Part | H23: 燦坤 | I23: 燦坤 | J23: SAL | K23: TW01442600 | L23: 燦坤實業股份有限公司 | M23: TW014426A1 | N23: 燦坤 | O23: TWSG001699 | P23: 626嘉義新港燦坤 | Q23: S | S23: 626 | X23: TW012676 | Z23: 6956800* | AE23: 616 | AG23: 嘉義縣新港鄉中山路72巷2-3號 | AK23: TW | AL23: * | AN23: D | AO23: X | AQ23: 2025.11.25 14:58:32 | AR23: 정한석 hanseok.jung@lgepartner.com | AS23: 2026.06.26 20:03:53 | AT23: 노용훈 yonghoon1.noh@lgepartner.com | AU23: EATT | AV23: [LGETT] Common | AW23: Domestic | AX23: 45986
A24: 陳勇志 | B24: MMCS | C24: 全聯 | E24: TW014431A1 | F24: 大潤發總公司 | G24: MM Dept. | H24: 大潤發 | I24: 全聯 | J24: SAL | K24: TW01443100 | L24: 大潤發流通事業股份有限公司 | M24: TW014431A1 | N24: 大潤發總公司 | O24: TWSG002791 | P24: 75大潤發供應鍊(外箱) | Q24: S | S24: MM000229-S | X24: TW012676 | Z24: 9716556* | AE24: 328 | AG24: 桃園市觀音鄉上大村大湖路一段298號(外箱) | AK24: TW | AL24: 大潤發觀音倉(外箱) | AN24: D | AO24: X | AQ24: 2025.11.25 14:58:36 | AR24: 정한석 hanseok.jung@lgepartner.com | AS24: 2026.06.26 20:09:11 | AT24: 노용훈 yonghoon1.noh@lgepartner.com | AU24: EATT | AV24: [LGETT] Common | AW24: Domestic | AX24: 45986
A25: 林威豪 | B25: 桃竹營銷處 | C25: 專售店 | E25: TW219348A1 | F25: 克拉企業 | G25: Dealer Sales_TaoChu Team | H25: 桃竹營銷處 | I25: 專售店 | J25: SAL | K25: TW21934800 | L25: 克拉企業 | M25: TW219348A1 | N25: 克拉企業 | O25: TWSG001354 | P25: 克拉企業(忠義倉) | Q25: S | S25: DL004120-S | X25: TW012676 | Z25: 6967086* | AE25: 333 | AG25: 桃園市龜山區忠義路一段1043巷42弄109號 | AK25: TW | AL25: * | AN25: D | AO25: X | AQ25: 2025.11.25 14:58:30 | AR25: 정한석 hanseok.jung@lgepartner.com | AS25: 2026.06.26 20:09:27 | AT25: 노용훈 yonghoon1.noh@lgepartner.com | AU25: EATT | AV25: [LGETT] Common | AW25: Domestic | AX25: 45986
A26: 江柏慶 | B26: 嘉南營銷處 | C26: DC店 | E26: TW010966A1 | F26: 信福電器 | G26: Dealer Sales_ChiaNan Team | H26: 嘉南營銷處 | I26: DC店 | J26: SAL | K26: TW01096600 | L26: 信福電器有限公司 | M26: TW010966A1 | N26: 信福電器 | O26: TWSG001919 | P26: 信福電器(路竹民族) | Q26: S | S26: DL004018-S | X26: TW012676 | Z26: 6927921* | AE26: 821 | AG26: 高雄市路竹區民族路132號 | AK26: TW | AL26: * | AN26: D | AO26: X | AQ26: 2025.11.25 14:58:41 | AR26: 정한석 hanseok.jung@lgepartner.com | AS26: 2026.06.26 20:09:54 | AT26: 노용훈 yonghoon1.noh@lgepartner.com | AU26: EATT | AV26: [LGETT] Common | AW26: Domestic | AX26: 45986
A27: 陳勇志 | B27: MMCS | C27: 全聯 | E27: TW018211A1 | F27: 大潤發嘉義 | G27: MM Part | H27: 大潤發 | I27: 全聯 | J27: SAL | K27: TW01821100 | L27: 大潤發流通事業股份有限公司嘉義分公司 | M27: TW018211A1 | N27: 大潤發嘉義 | O27: TWSG001648 | P27: 36大潤發嘉義 | Q27: S | S27: MM000130 | X27: TW012676 | Z27: 2843616* | AE27: 600 | AG27: 嘉義市博愛路2段281號 | AK27: TW | AL27: 大潤發流通事業股份有限公司 | AN27: D | AO27: X | AQ27: 2025.11.25 14:58:32 | AR27: 정한석 hanseok.jung@lgepartner.com | AS27: 2026.06.26 20:09:54 | AT27: 노용훈 yonghoon1.noh@lgepartner.com | AU27: EATT | AV27: [LGETT] Common | AW27: Domestic | AX27: 45986
A28: #N/A | B28: #N/A | C28: DC店 | E28: TW018373A1 | F28: 新秀國際企業有限公司 | G28: Dealer Sales_Taipei Team | H28: 台北營銷處 | I28: DC店 | J28: SAL | K28: TW01837300 | L28: 新秀國際企業 | M28: TW018373A1 | N28: 新秀國際企業有限公司 | O28: TWSG003053 | P28: 新秀國際-中壢元化店 | Q28: S | S28: DL003636 | X28: TW012676 | Z28: 5096891* | AE28: 320 | AG28: 桃園縣中壢市元化路2段30號1樓 | AK28: TW | AL28: 王鵬凱 | AN28: D | AO28: X | AQ28: 2025.11.25 14:58:28 | AR28: 정한석 hanseok.jung@lgepartner.com | AS28: 2026.06.26 20:10:05 | AT28: 노용훈 yonghoon1.noh@lgepartner.com | AU28: EATT | AV28: [LGETT] Common | AW28: Domestic | AX28: 45986
A29: 蔣承孝 | B29: 高屏營銷處 | C29: 專售店 | E29: TW219617A1 | F29: 九三電器有限公司 | G29: Dealer Sales_KaoPing Team | H29: 高屏營銷處 | I29: 專售店 | J29: SAL | K29: TW21945500 | L29: 九三電器有限公司 | M29: TW219617A1 | N29: 九三電器有限公司 | O29: TWSG002931 | P29: 九三電器(路竹倉) | Q29: S | S29: DL004124-S | X29: TW012676 | Z29: 2466809* | AE29: 821 | AG29: 高雄市路竹區民族路132號 | AK29: TW | AL29: 蘇泳瑄 | AM29: 0956168517 | AN29: D | AO29: X | AQ29: 2025.11.25 14:58:34 | AR29: 정한석 hanseok.jung@lgepartner.com | AS29: 2026.06.26 20:21:27 | AT29: 노용훈 yonghoon1.noh@lgepartner.com | AU29: EATT | AV29: [LGETT] Common | AW29: Domestic | AX29: 45986
A30: 陳志豐 | B30: 高屏營銷處 | C30: 專售店 | E30: TW013493A1 | F30: 晉宏電器 | G30: Dealer Sales_KaoPing Team | H30: 高屏營銷處 | I30: 專售店 | J30: SAL | K30: TW01349300 | L30: 晉宏電器行 | M30: TW013493A1 | N30: 晉宏電器 | O30: TWSG001177 | P30: 晉宏電器(送貨地址) | Q30: S | S30: DL002745 | X30: TW012676 | Z30: 9096489* | AE30: 928 | AG30: 屏東縣東港鎮中正路228號 | AK30: TW | AL30: 晉宏電器行(送貨地址) | AN30: D | AO30: X | AQ30: 2025.11.25 14:58:32 | AR30: 정한석 hanseok.jung@lgepartner.com | AS30: 2026.06.26 20:26:02 | AT30: 노용훈 yonghoon1.noh@lgepartner.com | AU30: EATT | AV30: [LGETT] Common | AW30: Domestic | AX30: 45986
A31: 葉作仁 | B31: 桃竹營銷處 | C31: 一般店 | E31: TW012596A1 | F31: 桃竹苗電器 | G31: Dealer Sales_TaoChu Team | H31: 桃竹營銷處 | I31: 一般店 | J31: SAL | K31: TW01259600 | L31: 桃竹苗電器有限公司 | M31: TW012596A1 | N31: 桃竹苗電器 | O31: TWSG003515 | P31: 桃竹苗電器(平鎮水廠路) | Q31: S | S31: DL004478-S | X31: TW012676 | Z31: 8952776* | AE31: 324 | AG31: 桃園市平鎮區水廠路12號 | AK31: TW | AL31: * 李文旭 | AN31: M | AO31: X | AQ31: 2026.02.06 08:00:06 | AR31: B_SS_ZZZZ001 | AS31: 2026.06.26 21:32:27 | AT31: 노용훈 yonghoon1.noh@lgepartner.com | AU31: EATT | AV31: [LGETT] Common | AW31: Domestic | AX31: 46059
A32: 連承剛 | B32: 百貨 | C32: 百貨 | E32: TW219296A1 | F32: 丹意企業 | G32: Department Store Team | H32: 百貨 | I32: 百貨 | J32: SAL | K32: TW21929600 | L32: 丹意企業 | M32: TW219296A1 | N32: 丹意企業 | O32: TWSG003640 | P32: 丹意(B&O)-板橋大遠百門市 | Q32: S | S32: DL003709-S | X32: TW012676 | Z32: 2846540* | AE32: 220 | AG32: 新北市板橋區新站路28號2樓 | AK32: TW | AL32: * 楊昆松 | AN32: M | AO32: X | AQ32: 2026.05.16 08:00:04 | AR32: B_SS_ZZZZ001 | AS32: 2026.06.26 21:32:41 | AT32: 노용훈 yonghoon1.noh@lgepartner.com | AU32: EATT | AV32: [LGETT] Common | AW32: Domestic | AX32: 46158
A33: 錢亮均 | B33: 台北營銷處 | C33: 一般店 | E33: TW011559A1 | F33: 宏億電器行 | G33: LGETT | H33: 台北營銷處 | I33: 一般店 | J33: SAL | K33: TW01155900 | L33: 宏億電器行 | M33: TW011559A1 | N33: 宏億電器行 | O33: TWSG003576 | P33: 宏億電器行 | Q33: S | S33: TW003045-S | X33: TW012676 | Z33: 9586982* | AE33: 221 | AG33: 新北市汐止區建成路３７巷９號 | AK33: TW | AL33: 廖儒慶 | AM33: 0955500280 | AN33: M | AO33: X | AQ33: 2026.04.14 08:00:04 | AR33: B_SS_ZZZZ001 | AS33: 2026.06.26 21:32:44 | AT33: 노용훈 yonghoon1.noh@lgepartner.com | AU33: EATT | AV33: [LGETT] Common | AW33: Domestic | AX33: 46126
A34: 褚家鳴 | B34: 桃竹營銷處 | C34: DC店 | E34: TW010884A1 | F34: 金一電器 | G34: Dealer Sales_TaoChu Team | H34: 桃竹營銷處 | I34: DC店 | J34: SAL | K34: TW01088400 | L34: 金一電器有限公司 | M34: TW010884A1 | N34: 金一電器 | O34: TWSG003459 | P34: 金一電器(鳳坑村倉) | Q34: S | S34: DL004454-S | X34: TW012676 | Z34: 2213799* | AE34: 304 | AG34: 新竹縣新豐鄉鳳坑村15鄰649號 | AK34: TW | AL34: * 戴老闆 | AN34: M | AO34: X | AQ34: 2025.12.23 08:38:03 | AR34: 김승윤 seungyun2.kim@lgepartner.com | AS34: 2026.06.26 21:39:48 | AT34: 노용훈 yonghoon1.noh@lgepartner.com | AU34: EATT | AV34: [LGETT] Common | AW34: Domestic | AX34: 46014
A35: 錢亮均 | B35: 台北營銷處 | C35: 一般店 | E35: TW019189A1 | F35: 怡沃拉國際有限公司 | G35: LGETT | H35: 台北營銷處 | I35: 一般店 | J35: SAL | K35: TW01918900 | L35: 怡沃拉國際有限公司 | M35: TW019189A1 | N35: 怡沃拉國際有限公司 | O35: TWSG003647 | P35: 怡沃拉(汐止自助倉) | Q35: S | S35: DL004521-S | X35: TW012676 | Z35: 6057419* | AE35: 221 | AG35: 新北市汐止區汐萬路二段228巷18弄9 號 | AK35: TW | AL35: * | AN35: M | AO35: X | AQ35: 2026.05.20 08:00:06 | AR35: B_SS_ZZZZ001 | AS35: 2026.06.26 21:51:35 | AT35: 노용훈 yonghoon1.noh@lgepartner.com | AU35: EATT | AV35: [LGETT] Common | AW35: Domestic | AX35: 46162
A36: 趙鵬凱 | B36: AC Team | C36: 一般店 | E36: TW219474A1 | F36: 瑞鴻家電 | G36: AC Team | H36: AC TEAM | I36: 一般店 | J36: SAL | K36: TW21947400 | L36: 瑞鴻家電 | M36: TW219474A1 | N36: 瑞鴻家電 | O36: TWSG003510 | P36: 瑞鴻家電 | Q36: S | S36: TW007538-S | X36: TW012676 | Z36: 2486522* | AE36: 503 | AG36: 彰化縣花壇鄉花壇村番花路臨7號 | AK36: TW | AL36: 賴有勝 | AM36: 04-7863747 | AN36: M | AO36: X | AQ36: 2026.02.03 08:00:05 | AR36: B_SS_ZZZZ001 | AS36: 2026.06.26 21:51:39 | AT36: 노용훈 yonghoon1.noh@lgepartner.com | AU36: EATT | AV36: [LGETT] Common | AW36: Domestic | AX36: 46056
A37: 施漢鵬 | B37: MMCS | C37: 好市多_富基 | E37: TW019257A1 | F37: 富基電通 | G37: MM Part | H37: 好市多 | I37: 好市多_富基 | J37: SAL | K37: TW01370200 | L37: 富基電通股份有限公司 | M37: TW019257A1 | N37: 富基電通 | O37: TWSG003618 | P37: 富基-好市多(林口倉) | Q37: S | S37: MM000274-S | X37: TW012676 | Z37: 2752554* | AE37: 244 | AG37: 新北市林口區南勢里9鄰33-12號 | AK37: TW | AL37: * | AN37: M | AO37: X | AQ37: 2026.04.23 08:00:07 | AR37: B_SS_ZZZZ001 | AS37: 2026.06.26 21:56:18 | AT37: 노용훈 yonghoon1.noh@lgepartner.com | AU37: EATT | AV37: [LGETT] Common | AW37: Domestic | AX37: 46135
A38: 廖婉婷 | B38: B2B2C | C38: B2B2C | E38: TW019240A1 | F38: 映象國際 | G38: LGETT | H38: B2B2C(B2B2C Part) | I38: B2B2C | J38: SAL | K38: TW01427400 | L38: 映象國際企業有限公司 | M38: TW019240A1 | N38: 映象國際 | O38: TWSG003493 | P38: 映象國際 | Q38: S | S38: TW007943-S | X38: TW012676 | Z38: 2432316* | AE38: 100 | AG38: 台北市中正區中華一路一段25號2樓 | AK38: TW | AL38: 高慧娟 | AM38: 0939113292 | AN38: M | AO38: X | AQ38: 2026.01.23 08:00:07 | AR38: B_SS_ZZZZ001 | AS38: 2026.06.26 22:21:12 | AT38: 노용훈 yonghoon1.noh@lgepartner.com | AU38: EATT | AV38: [LGETT] Common | AW38: Domestic | AX38: 46045
A39: 錢亮均 | B39: 台北營銷處 | C39: 一般店 | E39: TW019207A1 | F39: 華綺電器有限公司 | G39: LGETT | H39: 台北營銷處 | I39: 一般店 | J39: SAL | K39: TW01920700 | L39: 華綺電器有限公司 | M39: TW019207A1 | N39: 華綺電器有限公司 | O39: TWSG003458 | P39: 華綺電器有限公司 | Q39: S | S39: TW007914-S | X39: TW012676 | Z39: 7067075* | AE39: 241 | AG39: 新北市三重區正義北路337號1樓 | AK39: TW | AL39: 王蕓菁 | AM39: 0963626892 | AN39: M | AO39: X | AQ39: 2025.12.23 08:38:40 | AR39: 김승윤 seungyun2.kim@lgepartner.com | AS39: 2026.06.26 22:21:12 | AT39: 노용훈 yonghoon1.noh@lgepartner.com | AU39: EATT | AV39: [LGETT] Common | AW39: Domestic | AX39: 46014
A40: 施漢鵬 | B40: MMCS | C40: 好市多 | E40: TW009133A1 | F40: 好市多股份有限公司 | G40: MM Dept. | H40: 好市多 | I40: 好市多 | J40: SAL | K40: TW00913300 | L40: 好巿多股份有限公司 | M40: TW009133A1 | N40: 好市多股份有限公司 | O40: TWSG003686 | P40: 好巿多股份有限公司(網購-商業配送) | Q40: S | X40: TW012676 | AE40: 333 | AG40: 桃園市龜山區頂湖路58號4樓 | AK40: TW | AL40: * | AN40: D | AO40: X | AQ40: 2026.07.07 17:29:45 | AR40: 김승윤 seungyun2.kim@lgepartner.com | AS40: 0000.00.00 00:00:00 | AU40: EATT | AV40: [LGETT] Common | AW40: Domestic | AX40: 46210
...

Sheet 業務員
A1: Status | B1: Icon | C1: Sales Org. | D1: Dist.Ch. | E1: Distr.Type. | F1: Sold-To Party | G1: Sold-To Name | H1: Ship-To Party | I1: Ship-To Party Name | J1: Salesperson | K1: Salesperson Name | L1: Resignation Flag | M1: Resignation | N1: Department Code | O1: Department Name | P1: Dept. BA | Q1: Division | R1: Department Type | S1: Start Date | T1: End Date | U1: Security Dept.Code | V1: Security Dept. | W1: Inactive | X1: Created By | Y1: Created On | Z1: Created At | AA1: Changed By | AB1: Changed On | AC1: Changed At | AD1: Message | AE1: 業務員 | AF1: 業務員單位
C2: TT00 | D2: 10 | E2: OM | F2: TW019228A1 | G2: 億電通國際 | J2: TT001518 | K2: 羅 時景 | L2: A | M2: Active | N2: 12104017 | O2: LGETT Co-President | P2: SAL | R2: STAFF | S2: 46038 | T2: 401769 | U2: 11000151 | V2: LGETT | W2: false | X2: changsun.yang_chang sun Yang | Y2: 46203 | Z2: 0.80075231 | AA2: changsun.yang_chang sun Yang | AB2: 46203 | AC2: 0.80075231 | AE2: =IFERROR(VLOOKUP(J2&K2,對照!A:C,2,0),"") -> 羅時景 | AF2: =IFERROR(VLOOKUP(J2&K2,對照!A:C,3,0),"") -> ETC
C3: TT00 | D3: 10 | E3: OM | F3: TW019228A1 | G3: 億電通國際 | H3: TWSG003472 | I3: 億電通國際 | J3: TT001518 | K3: 羅 時景 | L3: A | M3: Active | N3: 12104017 | O3: LGETT Co-President | P3: SAL | R3: STAFF | S3: 46038 | T3: 401769 | U3: 11000151 | V3: LGETT | W3: false | X3: changsun.yang_chang sun Yang | Y3: 46203 | Z3: 0.80075231 | AA3: changsun.yang_chang sun Yang | AB3: 46203 | AC3: 0.80075231 | AE3: =IFERROR(VLOOKUP(J3&K3,對照!A:C,2,0),"") -> 羅時景 | AF3: =IFERROR(VLOOKUP(J3&K3,對照!A:C,3,0),"") -> ETC
C4: TT00 | D4: 10 | E4: OM | F4: TW219504A1 | G4: 九三商行 | J4: TT001518 | K4: 羅 時景 | L4: A | M4: Active | N4: 12104017 | O4: LGETT Co-President | P4: SAL | R4: STAFF | S4: 46038 | T4: 401769 | U4: 11000151 | V4: LGETT | W4: false | X4: changsun.yang_chang sun Yang | Y4: 46203 | Z4: 0.80075231 | AA4: changsun.yang_chang sun Yang | AB4: 46203 | AC4: 0.80075231 | AE4: =IFERROR(VLOOKUP(J4&K4,對照!A:C,2,0),"") -> 羅時景 | AF4: =IFERROR(VLOOKUP(J4&K4,對照!A:C,3,0),"") -> ETC
C5: TT00 | D5: 10 | E5: OM | F5: TW019311A1 | G5: 捷超工程行 | J5: TT230597 | K5: 顏 豪志 | L5: A | M5: Active | N5: 11007247 | O5: Dealer Sales_KaoPing Team | P5: SAL | R5: SALES | S5: 46252 | T5: 2958465 | U5: 11000151 | V5: LGETT | W5: false | X5: yuchin.chen_Yuchin Chen | Y5: 46252 | Z5: 0.41643519 | AA5: yuchin.chen_Yuchin Chen | AB5: 46252 | AC5: 0.41643519 | AE5: =IFERROR(VLOOKUP(J5&K5,對照!A:C,2,0),"") -> 顏豪志 | AF5: =IFERROR(VLOOKUP(J5&K5,對照!A:C,3,0),"") -> 高屏營銷處
C6: TT00 | D6: 10 | E6: OM | F6: TW018773A1 | G6: 集盛股份有限公司 | H6: TWSG000389 | I6: 集盛(股)公司(東源湖內) | J6: TT230597 | K6: 顏 豪志 | L6: A | M6: Active | N6: 11007247 | O6: Dealer Sales_KaoPing Team | P6: SAL | R6: SALES | S6: 46219 | T6: 2958465 | U6: 11000151 | V6: LGETT | W6: false | X6: yuchin.chen_Yuchin Chen | Y6: 46219 | Z6: 0.68414352 | AA6: yuchin.chen_Yuchin Chen | AB6: 46219 | AC6: 0.68414352 | AE6: =IFERROR(VLOOKUP(J6&K6,對照!A:C,2,0),"") -> 顏豪志 | AF6: =IFERROR(VLOOKUP(J6&K6,對照!A:C,3,0),"") -> 高屏營銷處
C7: TT00 | D7: 10 | E7: OM | F7: TW014723A1 | G7: 翠亨企業 | H7: TW014723 | I7: 翠亨企業股份有限公司 | J7: TT230597 | K7: 顏 豪志 | L7: A | M7: Active | N7: 11007247 | O7: Dealer Sales_KaoPing Team | P7: SAL | R7: SALES | S7: 46204 | T7: 401769 | U7: 11000151 | V7: LGETT | W7: false | X7: changsun.yang_chang sun Yang | Y7: 46203 | Z7: 0.80075231 | AA7: changsun.yang_chang sun Yang | AB7: 46203 | AC7: 0.80075231 | AE7: =IFERROR(VLOOKUP(J7&K7,對照!A:C,2,0),"") -> 顏豪志 | AF7: =IFERROR(VLOOKUP(J7&K7,對照!A:C,3,0),"") -> 高屏營銷處
C8: TT00 | D8: 10 | E8: OM | F8: TW014723A1 | G8: 翠亨企業 | H8: TWSG002474 | I8: 翠亨企業(路竹倉) | J8: TT230597 | K8: 顏 豪志 | L8: A | M8: Active | N8: 11007247 | O8: Dealer Sales_KaoPing Team | P8: SAL | R8: SALES | S8: 46204 | T8: 401769 | U8: 11000151 | V8: LGETT | W8: false | X8: changsun.yang_chang sun Yang | Y8: 46203 | Z8: 0.80075231 | AA8: changsun.yang_chang sun Yang | AB8: 46203 | AC8: 0.80075231 | AE8: =IFERROR(VLOOKUP(J8&K8,對照!A:C,2,0),"") -> 顏豪志 | AF8: =IFERROR(VLOOKUP(J8&K8,對照!A:C,3,0),"") -> 高屏營銷處
C9: TT00 | D9: 10 | E9: OM | F9: TW014723A1 | G9: 翠亨企業 | J9: TT230597 | K9: 顏 豪志 | L9: A | M9: Active | N9: 11007247 | O9: Dealer Sales_KaoPing Team | P9: SAL | R9: SALES | S9: 46204 | T9: 401769 | U9: 11000151 | V9: LGETT | W9: false | X9: changsun.yang_chang sun Yang | Y9: 46203 | Z9: 0.80075231 | AA9: changsun.yang_chang sun Yang | AB9: 46203 | AC9: 0.80075231 | AE9: =IFERROR(VLOOKUP(J9&K9,對照!A:C,2,0),"") -> 顏豪志 | AF9: =IFERROR(VLOOKUP(J9&K9,對照!A:C,3,0),"") -> 高屏營銷處
C10: TT00 | D10: 10 | E10: OM | F10: TW219262A1 | G10: 立欣電器行 | J10: TT230597 | K10: 顏 豪志 | L10: A | M10: Active | N10: 11007247 | O10: Dealer Sales_KaoPing Team | P10: SAL | R10: SALES | S10: 46204 | T10: 401769 | U10: 11000151 | V10: LGETT | W10: false | X10: changsun.yang_chang sun Yang | Y10: 46203 | Z10: 0.80075231 | AA10: changsun.yang_chang sun Yang | AB10: 46203 | AC10: 0.80075231 | AE10: =IFERROR(VLOOKUP(J10&K10,對照!A:C,2,0),"") -> 顏豪志 | AF10: =IFERROR(VLOOKUP(J10&K10,對照!A:C,3,0),"") -> 高屏營銷處
C11: TT00 | D11: 10 | E11: OM | F11: TW219540A1 | G11: 弘力電器行 | J11: TT230597 | K11: 顏 豪志 | L11: A | M11: Active | N11: 11007247 | O11: Dealer Sales_KaoPing Team | P11: SAL | R11: SALES | S11: 46204 | T11: 401769 | U11: 11000151 | V11: LGETT | W11: false | X11: changsun.yang_chang sun Yang | Y11: 46203 | Z11: 0.80075231 | AA11: changsun.yang_chang sun Yang | AB11: 46203 | AC11: 0.80075231 | AE11: =IFERROR(VLOOKUP(J11&K11,對照!A:C,2,0),"") -> 顏豪志 | AF11: =IFERROR(VLOOKUP(J11&K11,對照!A:C,3,0),"") -> 高屏營銷處
C12: TT00 | D12: 10 | E12: OM | F12: TW014331A1 | G12: 上眾電器 | H12: TWSG003666 | I12: 上眾(新生倉庫) | J12: TT230597 | K12: 顏 豪志 | L12: A | M12: Active | N12: 11007247 | O12: Dealer Sales_KaoPing Team | P12: SAL | R12: SALES | S12: 46196 | T12: 401769 | U12: 11000151 | V12: LGETT | W12: false | X12: changsun.yang_chang sun Yang | Y12: 46203 | Z12: 0.80075231 | AA12: changsun.yang_chang sun Yang | AB12: 46203 | AC12: 0.80075231 | AE12: =IFERROR(VLOOKUP(J12&K12,對照!A:C,2,0),"") -> 顏豪志 | AF12: =IFERROR(VLOOKUP(J12&K12,對照!A:C,3,0),"") -> 高屏營銷處
C13: TT00 | D13: 10 | E13: OM | F13: TW018785A1 | G13: 羅森數位有限公司 | J13: TT230597 | K13: 顏 豪志 | L13: A | M13: Active | N13: 11007247 | O13: Dealer Sales_KaoPing Team | P13: SAL | R13: SALES | S13: 46124 | T13: 401769 | U13: 11000151 | V13: LGETT | W13: false | X13: changsun.yang_chang sun Yang | Y13: 46203 | Z13: 0.80075231 | AA13: changsun.yang_chang sun Yang | AB13: 46203 | AC13: 0.80075231 | AE13: =IFERROR(VLOOKUP(J13&K13,對照!A:C,2,0),"") -> 顏豪志 | AF13: =IFERROR(VLOOKUP(J13&K13,對照!A:C,3,0),"") -> 高屏營銷處
C14: TT00 | D14: 10 | E14: OM | F14: TW018785A1 | G14: 羅森數位有限公司 | H14: TWSG001992 | I14: 羅森數位(仁武倉) | J14: TT230597 | K14: 顏 豪志 | L14: A | M14: Active | N14: 11007247 | O14: Dealer Sales_KaoPing Team | P14: SAL | R14: SALES | S14: 46124 | T14: 401769 | U14: 11000151 | V14: LGETT | W14: false | X14: changsun.yang_chang sun Yang | Y14: 46203 | Z14: 0.80075231 | AA14: changsun.yang_chang sun Yang | AB14: 46203 | AC14: 0.80075231 | AE14: =IFERROR(VLOOKUP(J14&K14,對照!A:C,2,0),"") -> 顏豪志 | AF14: =IFERROR(VLOOKUP(J14&K14,對照!A:C,3,0),"") -> 高屏營銷處
C15: TT00 | D15: 10 | E15: OM | F15: TW018785A1 | G15: 羅森數位有限公司 | H15: TWSG003518 | I15: 羅森數位(佳事達自租倉) | J15: TT230597 | K15: 顏 豪志 | L15: A | M15: Active | N15: 11007247 | O15: Dealer Sales_KaoPing Team | P15: SAL | R15: SALES | S15: 46124 | T15: 401769 | U15: 11000151 | V15: LGETT | W15: false | X15: changsun.yang_chang sun Yang | Y15: 46203 | Z15: 0.80075231 | AA15: changsun.yang_chang sun Yang | AB15: 46203 | AC15: 0.80075231 | AE15: =IFERROR(VLOOKUP(J15&K15,對照!A:C,2,0),"") -> 顏豪志 | AF15: =IFERROR(VLOOKUP(J15&K15,對照!A:C,3,0),"") -> 高屏營銷處
C16: TT00 | D16: 10 | E16: OM | F16: TW219261A1 | G16: 允丞電器 | J16: TT230597 | K16: 顏 豪志 | L16: A | M16: Active | N16: 11007247 | O16: Dealer Sales_KaoPing Team | P16: SAL | R16: SALES | S16: 46123 | T16: 401769 | U16: 11000151 | V16: LGETT | W16: false | X16: changsun.yang_chang sun Yang | Y16: 46203 | Z16: 0.80075231 | AA16: changsun.yang_chang sun Yang | AB16: 46203 | AC16: 0.80075231 | AE16: =IFERROR(VLOOKUP(J16&K16,對照!A:C,2,0),"") -> 顏豪志 | AF16: =IFERROR(VLOOKUP(J16&K16,對照!A:C,3,0),"") -> 高屏營銷處
C17: TT00 | D17: 10 | E17: OM | F17: TW219317A1 | G17: 九九電器工程 | J17: TT230597 | K17: 顏 豪志 | L17: A | M17: Active | N17: 11007247 | O17: Dealer Sales_KaoPing Team | P17: SAL | R17: SALES | S17: 46123 | T17: 401769 | U17: 11000151 | V17: LGETT | W17: false | X17: changsun.yang_chang sun Yang | Y17: 46203 | Z17: 0.80075231 | AA17: changsun.yang_chang sun Yang | AB17: 46203 | AC17: 0.80075231 | AE17: =IFERROR(VLOOKUP(J17&K17,對照!A:C,2,0),"") -> 顏豪志 | AF17: =IFERROR(VLOOKUP(J17&K17,對照!A:C,3,0),"") -> 高屏營銷處
C18: TT00 | D18: 10 | E18: OM | F18: TW019173A1 | G18: 樂嘉家電 | H18: TWSG003198 | I18: 樂嘉家電(秀翔瑞揚倉) | J18: TT230597 | K18: 顏 豪志 | L18: A | M18: Active | N18: 11007247 | O18: Dealer Sales_KaoPing Team | P18: SAL | R18: SALES | S18: 45909 | T18: 401769 | U18: 11000151 | V18: LGETT | W18: false | X18: changsun.yang_chang sun Yang | Y18: 46203 | Z18: 0.80075231 | AA18: changsun.yang_chang sun Yang | AB18: 46203 | AC18: 0.80075231 | AE18: =IFERROR(VLOOKUP(J18&K18,對照!A:C,2,0),"") -> 顏豪志 | AF18: =IFERROR(VLOOKUP(J18&K18,對照!A:C,3,0),"") -> 高屏營銷處
C19: TT00 | D19: 10 | E19: OM | F19: TW019173A1 | G19: 樂嘉家電 | H19: TWSG003199 | I19: 樂嘉家電(輜汽倉) | J19: TT230597 | K19: 顏 豪志 | L19: A | M19: Active | N19: 11007247 | O19: Dealer Sales_KaoPing Team | P19: SAL | R19: SALES | S19: 45909 | T19: 401769 | U19: 11000151 | V19: LGETT | W19: false | X19: changsun.yang_chang sun Yang | Y19: 46203 | Z19: 0.80075231 | AA19: changsun.yang_chang sun Yang | AB19: 46203 | AC19: 0.80075231 | AE19: =IFERROR(VLOOKUP(J19&K19,對照!A:C,2,0),"") -> 顏豪志 | AF19: =IFERROR(VLOOKUP(J19&K19,對照!A:C,3,0),"") -> 高屏營銷處
C20: TT00 | D20: 10 | E20: OM | F20: TW019173A1 | G20: 樂嘉家電 | H20: TWSG003200 | I20: 樂嘉家電(東源倉) | J20: TT230597 | K20: 顏 豪志 | L20: A | M20: Active | N20: 11007247 | O20: Dealer Sales_KaoPing Team | P20: SAL | R20: SALES | S20: 45909 | T20: 401769 | U20: 11000151 | V20: LGETT | W20: false | X20: changsun.yang_chang sun Yang | Y20: 46203 | Z20: 0.80075231 | AA20: changsun.yang_chang sun Yang | AB20: 46203 | AC20: 0.80075231 | AE20: =IFERROR(VLOOKUP(J20&K20,對照!A:C,2,0),"") -> 顏豪志 | AF20: =IFERROR(VLOOKUP(J20&K20,對照!A:C,3,0),"") -> 高屏營銷處
C21: TT00 | D21: 10 | E21: OM | F21: TW019173A1 | G21: 樂嘉家電 | H21: TWSG003201 | I21: 樂嘉家電(三多門市) | J21: TT230597 | K21: 顏 豪志 | L21: A | M21: Active | N21: 11007247 | O21: Dealer Sales_KaoPing Team | P21: SAL | R21: SALES | S21: 45909 | T21: 401769 | U21: 11000151 | V21: LGETT | W21: false | X21: changsun.yang_chang sun Yang | Y21: 46203 | Z21: 0.80075231 | AA21: changsun.yang_chang sun Yang | AB21: 46203 | AC21: 0.80075231 | AE21: =IFERROR(VLOOKUP(J21&K21,對照!A:C,2,0),"") -> 顏豪志 | AF21: =IFERROR(VLOOKUP(J21&K21,對照!A:C,3,0),"") -> 高屏營銷處
C22: TT00 | D22: 10 | E22: OM | F22: TW019173A1 | G22: 樂嘉家電 | J22: TT230597 | K22: 顏 豪志 | L22: A | M22: Active | N22: 11007247 | O22: Dealer Sales_KaoPing Team | P22: SAL | R22: SALES | S22: 45904 | T22: 401769 | U22: 11000151 | V22: LGETT | W22: false | X22: changsun.yang_chang sun Yang | Y22: 46203 | Z22: 0.80075231 | AA22: changsun.yang_chang sun Yang | AB22: 46203 | AC22: 0.80075231 | AE22: =IFERROR(VLOOKUP(J22&K22,對照!A:C,2,0),"") -> 顏豪志 | AF22: =IFERROR(VLOOKUP(J22&K22,對照!A:C,3,0),"") -> 高屏營銷處
C23: TT00 | D23: 10 | E23: OM | F23: TW019173A1 | G23: 樂嘉家電 | H23: TWSG003196 | I23: 樂嘉家電有限公司 | J23: TT230597 | K23: 顏 豪志 | L23: A | M23: Active | N23: 11007247 | O23: Dealer Sales_KaoPing Team | P23: SAL | R23: SALES | S23: 45904 | T23: 401769 | U23: 11000151 | V23: LGETT | W23: false | X23: changsun.yang_chang sun Yang | Y23: 46203 | Z23: 0.80075231 | AA23: changsun.yang_chang sun Yang | AB23: 46203 | AC23: 0.80075231 | AE23: =IFERROR(VLOOKUP(J23&K23,對照!A:C,2,0),"") -> 顏豪志 | AF23: =IFERROR(VLOOKUP(J23&K23,對照!A:C,3,0),"") -> 高屏營銷處
C24: TT00 | D24: 10 | E24: OM | F24: TW018614A1 | G24: 鴻昇興業行 | J24: TT230597 | K24: 顏 豪志 | L24: A | M24: Active | N24: 11007247 | O24: Dealer Sales_KaoPing Team | P24: SAL | R24: SALES | S24: 45775 | T24: 401769 | U24: 11000151 | V24: LGETT | W24: false | X24: changsun.yang_chang sun Yang | Y24: 46203 | Z24: 0.80075231 | AA24: changsun.yang_chang sun Yang | AB24: 46203 | AC24: 0.80075231 | AE24: =IFERROR(VLOOKUP(J24&K24,對照!A:C,2,0),"") -> 顏豪志 | AF24: =IFERROR(VLOOKUP(J24&K24,對照!A:C,3,0),"") -> 高屏營銷處
C25: TT00 | D25: 10 | E25: OM | F25: TW219426A1 | G25: 章記企業有限公司 | H25: TWSG002365 | I25: 章記(橋頭倉) | J25: TT230597 | K25: 顏 豪志 | L25: A | M25: Active | N25: 11007247 | O25: Dealer Sales_KaoPing Team | P25: SAL | R25: SALES | S25: 45771 | T25: 401769 | U25: 11000151 | V25: LGETT | W25: false | X25: changsun.yang_chang sun Yang | Y25: 46203 | Z25: 0.80075231 | AA25: changsun.yang_chang sun Yang | AB25: 46203 | AC25: 0.80075231 | AE25: =IFERROR(VLOOKUP(J25&K25,對照!A:C,2,0),"") -> 顏豪志 | AF25: =IFERROR(VLOOKUP(J25&K25,對照!A:C,3,0),"") -> 高屏營銷處
C26: TT00 | D26: 10 | E26: OM | F26: TW219578A1 | G26: 培芝家電快速服務中心 | H26: TWSG002665 | I26: 培芝家電(三多門市) | J26: TT230597 | K26: 顏 豪志 | L26: A | M26: Active | N26: 11007247 | O26: Dealer Sales_KaoPing Team | P26: SAL | R26: SALES | S26: 45712 | T26: 401769 | U26: 11000151 | V26: LGETT | W26: false | X26: changsun.yang_chang sun Yang | Y26: 46203 | Z26: 0.80075231 | AA26: changsun.yang_chang sun Yang | AB26: 46203 | AC26: 0.80075231 | AE26: =IFERROR(VLOOKUP(J26&K26,對照!A:C,2,0),"") -> 顏豪志 | AF26: =IFERROR(VLOOKUP(J26&K26,對照!A:C,3,0),"") -> 高屏營銷處
C27: TT00 | D27: 10 | E27: OM | F27: TW219578A1 | G27: 培芝家電快速服務中心 | H27: TWSG002664 | I27: 培芝家電(東源倉庫) | J27: TT230597 | K27: 顏 豪志 | L27: A | M27: Active | N27: 11007247 | O27: Dealer Sales_KaoPing Team | P27: SAL | R27: SALES | S27: 45712 | T27: 401769 | U27: 11000151 | V27: LGETT | W27: false | X27: changsun.yang_chang sun Yang | Y27: 46203 | Z27: 0.80075231 | AA27: changsun.yang_chang sun Yang | AB27: 46203 | AC27: 0.80075231 | AE27: =IFERROR(VLOOKUP(J27&K27,對照!A:C,2,0),"") -> 顏豪志 | AF27: =IFERROR(VLOOKUP(J27&K27,對照!A:C,3,0),"") -> 高屏營銷處
C28: TT00 | D28: 10 | E28: OM | F28: TW219578A1 | G28: 培芝家電快速服務中心 | H28: TWSG002663 | I28: 培芝家電(輜汽倉庫) | J28: TT230597 | K28: 顏 豪志 | L28: A | M28: Active | N28: 11007247 | O28: Dealer Sales_KaoPing Team | P28: SAL | R28: SALES | S28: 45712 | T28: 401769 | U28: 11000151 | V28: LGETT | W28: false | X28: changsun.yang_chang sun Yang | Y28: 46203 | Z28: 0.80075231 | AA28: changsun.yang_chang sun Yang | AB28: 46203 | AC28: 0.80075231 | AE28: =IFERROR(VLOOKUP(J28&K28,對照!A:C,2,0),"") -> 顏豪志 | AF28: =IFERROR(VLOOKUP(J28&K28,對照!A:C,3,0),"") -> 高屏營銷處
C29: TT00 | D29: 10 | E29: OM | F29: TW219578A1 | G29: 培芝家電快速服務中心 | H29: TWSG002666 | I29: 培芝家電快速服務中心 | J29: TT230597 | K29: 顏 豪志 | L29: A | M29: Active | N29: 11007247 | O29: Dealer Sales_KaoPing Team | P29: SAL | R29: SALES | S29: 45681 | T29: 401769 | U29: 11000151 | V29: LGETT | W29: false | X29: changsun.yang_chang sun Yang | Y29: 46203 | Z29: 0.80075231 | AA29: changsun.yang_chang sun Yang | AB29: 46203 | AC29: 0.80075231 | AE29: =IFERROR(VLOOKUP(J29&K29,對照!A:C,2,0),"") -> 顏豪志 | AF29: =IFERROR(VLOOKUP(J29&K29,對照!A:C,3,0),"") -> 高屏營銷處
C30: TT00 | D30: 10 | E30: OM | F30: TW219578A1 | G30: 培芝家電快速服務中心 | J30: TT230597 | K30: 顏 豪志 | L30: A | M30: Active | N30: 11007247 | O30: Dealer Sales_KaoPing Team | P30: SAL | R30: SALES | S30: 45681 | T30: 401769 | U30: 11000151 | V30: LGETT | W30: false | X30: changsun.yang_chang sun Yang | Y30: 46203 | Z30: 0.80075231 | AA30: changsun.yang_chang sun Yang | AB30: 46203 | AC30: 0.80075231 | AE30: =IFERROR(VLOOKUP(J30&K30,對照!A:C,2,0),"") -> 顏豪志 | AF30: =IFERROR(VLOOKUP(J30&K30,對照!A:C,3,0),"") -> 高屏營銷處
C31: TT00 | D31: 10 | E31: OM | F31: TW018773A1 | G31: 集盛股份有限公司 | H31: TWSG000200 | I31: 集盛(股)公司(彰化) | J31: TT230597 | K31: 顏 豪志 | L31: A | M31: Active | N31: 11007247 | O31: Dealer Sales_KaoPing Team | P31: SAL | R31: SALES | S31: 45642 | T31: 401769 | U31: 11000151 | V31: LGETT | W31: false | X31: changsun.yang_chang sun Yang | Y31: 46203 | Z31: 0.80075231 | AA31: changsun.yang_chang sun Yang | AB31: 46203 | AC31: 0.80075231 | AE31: =IFERROR(VLOOKUP(J31&K31,對照!A:C,2,0),"") -> 顏豪志 | AF31: =IFERROR(VLOOKUP(J31&K31,對照!A:C,3,0),"") -> 高屏營銷處
C32: TT00 | D32: 10 | E32: OM | F32: TW018773A1 | G32: 集盛股份有限公司 | H32: TWSG003070 | I32: 集盛(股)公司(台中烏日) | J32: TT230597 | K32: 顏 豪志 | L32: A | M32: Active | N32: 11007247 | O32: Dealer Sales_KaoPing Team | P32: SAL | R32: SALES | S32: 45579 | T32: 401769 | U32: 11000151 | V32: LGETT | W32: false | X32: changsun.yang_chang sun Yang | Y32: 46203 | Z32: 0.80075231 | AA32: changsun.yang_chang sun Yang | AB32: 46203 | AC32: 0.80075231 | AE32: =IFERROR(VLOOKUP(J32&K32,對照!A:C,2,0),"") -> 顏豪志 | AF32: =IFERROR(VLOOKUP(J32&K32,對照!A:C,3,0),"") -> 高屏營銷處
C33: TT00 | D33: 10 | E33: OM | F33: TW018773A1 | G33: 集盛股份有限公司 | H33: TWSG003069 | I33: 集盛(股)公司(桃園) | J33: TT230597 | K33: 顏 豪志 | L33: A | M33: Active | N33: 11007247 | O33: Dealer Sales_KaoPing Team | P33: SAL | R33: SALES | S33: 45579 | T33: 401769 | U33: 11000151 | V33: LGETT | W33: false | X33: changsun.yang_chang sun Yang | Y33: 46203 | Z33: 0.80075231 | AA33: changsun.yang_chang sun Yang | AB33: 46203 | AC33: 0.80075231 | AE33: =IFERROR(VLOOKUP(J33&K33,對照!A:C,2,0),"") -> 顏豪志 | AF33: =IFERROR(VLOOKUP(J33&K33,對照!A:C,3,0),"") -> 高屏營銷處
C34: TT00 | D34: 10 | E34: OM | F34: TW219468A1 | G34: 賽門音響企業社 | J34: TT230597 | K34: 顏 豪志 | L34: A | M34: Active | N34: 11007247 | O34: Dealer Sales_KaoPing Team | P34: SAL | R34: SALES | S34: 45215 | T34: 401769 | U34: 11000151 | V34: LGETT | W34: false | X34: changsun.yang_chang sun Yang | Y34: 46203 | Z34: 0.80075231 | AA34: changsun.yang_chang sun Yang | AB34: 46203 | AC34: 0.80075231 | AE34: =IFERROR(VLOOKUP(J34&K34,對照!A:C,2,0),"") -> 顏豪志 | AF34: =IFERROR(VLOOKUP(J34&K34,對照!A:C,3,0),"") -> 高屏營銷處
C35: TT00 | D35: 10 | E35: OM | F35: TW219426A1 | G35: 章記企業有限公司 | J35: TT230597 | K35: 顏 豪志 | L35: A | M35: Active | N35: 11007247 | O35: Dealer Sales_KaoPing Team | P35: SAL | R35: SALES | S35: 45108 | T35: 401769 | U35: 11000151 | V35: LGETT | W35: false | X35: changsun.yang_chang sun Yang | Y35: 46203 | Z35: 0.80075231 | AA35: changsun.yang_chang sun Yang | AB35: 46203 | AC35: 0.80075231 | AE35: =IFERROR(VLOOKUP(J35&K35,對照!A:C,2,0),"") -> 顏豪志 | AF35: =IFERROR(VLOOKUP(J35&K35,對照!A:C,3,0),"") -> 高屏營銷處
C36: TT00 | D36: 10 | E36: OM | F36: TW219337A1 | G36: 睿凡企業 | J36: TT230597 | K36: 顏 豪志 | L36: A | M36: Active | N36: 11007247 | O36: Dealer Sales_KaoPing Team | P36: SAL | R36: SALES | S36: 44259 | T36: 401769 | U36: 11000151 | V36: LGETT | W36: false | X36: changsun.yang_chang sun Yang | Y36: 46203 | Z36: 0.80075231 | AA36: changsun.yang_chang sun Yang | AB36: 46203 | AC36: 0.80075231 | AE36: =IFERROR(VLOOKUP(J36&K36,對照!A:C,2,0),"") -> 顏豪志 | AF36: =IFERROR(VLOOKUP(J36&K36,對照!A:C,3,0),"") -> 高屏營銷處
C37: TT00 | D37: 10 | E37: OM | F37: TW016815A1 | G37: 萊旺電器行 | J37: TT230597 | K37: 顏 豪志 | L37: A | M37: Active | N37: 11007247 | O37: Dealer Sales_KaoPing Team | P37: SAL | R37: SALES | S37: 44062 | T37: 401769 | U37: 11000151 | V37: LGETT | W37: false | X37: changsun.yang_chang sun Yang | Y37: 46203 | Z37: 0.80075231 | AA37: changsun.yang_chang sun Yang | AB37: 46203 | AC37: 0.80075231 | AE37: =IFERROR(VLOOKUP(J37&K37,對照!A:C,2,0),"") -> 顏豪志 | AF37: =IFERROR(VLOOKUP(J37&K37,對照!A:C,3,0),"") -> 高屏營銷處
C38: TT00 | D38: 10 | E38: OM | F38: TW018773A1 | G38: 集盛股份有限公司 | J38: TT230597 | K38: 顏 豪志 | L38: A | M38: Active | N38: 11007247 | O38: Dealer Sales_KaoPing Team | P38: SAL | R38: SALES | S38: 44054 | T38: 401769 | U38: 11000151 | V38: LGETT | W38: false | X38: changsun.yang_chang sun Yang | Y38: 46203 | Z38: 0.80075231 | AA38: changsun.yang_chang sun Yang | AB38: 46203 | AC38: 0.80075231 | AE38: =IFERROR(VLOOKUP(J38&K38,對照!A:C,2,0),"") -> 顏豪志 | AF38: =IFERROR(VLOOKUP(J38&K38,對照!A:C,3,0),"") -> 高屏營銷處
C39: TT00 | D39: 10 | E39: OM | F39: TW219307A1 | G39: 杉泰電器 | J39: TT230597 | K39: 顏 豪志 | L39: A | M39: Active | N39: 11007247 | O39: Dealer Sales_KaoPing Team | P39: SAL | R39: SALES | S39: 43908 | T39: 401769 | U39: 11000151 | V39: LGETT | W39: false | X39: changsun.yang_chang sun Yang | Y39: 46203 | Z39: 0.80075231 | AA39: changsun.yang_chang sun Yang | AB39: 46203 | AC39: 0.80075231 | AE39: =IFERROR(VLOOKUP(J39&K39,對照!A:C,2,0),"") -> 顏豪志 | AF39: =IFERROR(VLOOKUP(J39&K39,對照!A:C,3,0),"") -> 高屏營銷處
C40: TT00 | D40: 10 | E40: OM | F40: TW010987A1 | G40: 聯立貿易有限公司 | J40: TT230597 | K40: 顏 豪志 | L40: A | M40: Active | N40: 11007247 | O40: Dealer Sales_KaoPing Team | P40: SAL | R40: SALES | S40: 43691 | T40: 401769 | U40: 11000151 | V40: LGETT | W40: false | X40: changsun.yang_chang sun Yang | Y40: 46203 | Z40: 0.80075231 | AA40: changsun.yang_chang sun Yang | AB40: 46203 | AC40: 0.80075231 | AE40: =IFERROR(VLOOKUP(J40&K40,對照!A:C,2,0),"") -> 顏豪志 | AF40: =IFERROR(VLOOKUP(J40&K40,對照!A:C,3,0),"") -> 高屏營銷處
...

Sheet 對照
A1: Salesperson Name | B1: 業務員 | C1: 業務員單位 | L1: Sold to | M1: Legal Entity | N1: Sold Name | O1: 合併Sold to | P1: 合併Legal Entity | Q1: 合併Sold Name | R1: 特殊 | X1: 批店-Sold to | Y1: 批店-Sold Name | Z1: 特殊
A2: TT230713姜 泊昆 | B2: 姜泊昆 | C2: IT Part | L2: TW016267A1 | M2: TW01626700 | N2: 立誠電器有限公司 | O2: TW010823A1 | P2: TW01082300 | Q2: 鎮吉實業有限公司 | X2: TW010117A1 | Y2: 金長益電器 | Z2: 批店
A3: TT229829施 漢鵬 | B3: 施漢鵬 | C3: MMCS | L3: TW011309A1 | M3: TW01130900 | N3: 廣昌電器行 | O3: TW011309A1 | P3: TW01130900 | Q3: 廣昌電器行 | X3: TW010118A1 | Y3: 格愛陞 | Z3: 批店
A4: TT230775褚 家鳴 | B4: 褚家鳴 | C4: 桃竹營銷處 | L4: TW219353A1 | M4: TW21935300 | N4: 廣宜電器行 | O4: TW011309A1 | P4: TW01130900 | Q4: 廣昌電器行 | X4: TW010455A1 | Y4: 昇廣電器 | Z4: 批店
A5: TT001185陳 勇志 | B5: 陳勇志 | C5: MMCS | L5: TW016815A1 | M5: TW01681500 | N5: 萊旺電器行 | O5: TW012526A1 | P5: TW01252600 | Q5: 萊旺企業有限公司 | X5: TW010662A1 | Y5: 老雙億實業 | Z5: 批店
A6: TT230774粘 棋欽 | B6: 粘棋欽 | C6: 嘉南營銷處 | L6: TW013498A1 | M6: TW01349800 | N6: 同勝電器有限公司 | O6: TW013498A1 | P6: TW01349800 | Q6: 同勝電器有限公司 | X6: TW010706A1 | Y6: 統偉視聽工程有限公司 | Z6: AV店
A7: TT001436陳 俊宏 | B7: 陳俊宏(Rental) | C7: Rental | L7: TW219209A1 | M7: TW21920900 | N7: 統勝電器有限公司 | O7: TW013498A1 | P7: TW01349800 | Q7: 同勝電器有限公司 | X7: TW010823A1 | Y7: 鎮吉實業 | Z7: 批店
A8: TT001496歐 俊賢 | B8: 歐俊賢 | C8: 嘉南營銷處 | L8: TW219562A1 | M8: TW21956200 | N8: 甲組電器有限公司 | O8: TW013498A1 | P8: TW01349800 | Q8: 同勝電器有限公司 | X8: TW010830A1 | Y8: 承德國際有限公司 | Z8: AV店
A9: TT001305黃 坤鎮 | B9: 黃坤鎮 | C9: 嘉南營銷處 | L9: TW009961A1 | M9: TW00996100 | N9: 慧聲電器行 | O9: TW016117A1 | P9: TW01611700 | Q9: 慧榮電器有限公司 | X9: TW010841A1 | Y9: 佳禾 | Z9: 批店
A10: TT229769陳 慶全 | B10: 陳慶全 | C10: 台中營銷處 | L10: TW016117A1 | M10: TW01611700 | N10: 慧榮電器有限公司 | O10: TW016117A1 | P10: TW01611700 | Q10: 慧榮電器有限公司 | X10: TW010844A1 | Y10: 得興電器 | Z10: 批店
A11: TT230594江 柏慶 | B11: 江柏慶 | C11: 嘉南營銷處 | L11: TW219227A1 | M11: TW21922700 | N11: 鼎極家電有限公司 | O11: TW017534A1 | P11: TW01753400 | Q11: 國際極品科技有限公司 | X11: TW012439A1 | Y11: 悅鼎電器有限公司 | Z11: AV店
A12: TT001081陳 志豐 | B12: 陳志豐 | C12: 高屏營銷處 | L12: TW017534A1 | M12: TW01753400 | N12: 國際極品科技有限公司 | O12: TW017534A1 | P12: TW01753400 | Q12: 國際極品科技有限公司 | X12: TW012757A1 | Y12: 華笙音響企業有限公司 | Z12: AV店
A13: TT230543鄭 伊善 | B13: 鄭伊善 | C13: AC Team | L13: TW012602A1 | M13: TW01260200 | N13: 姿芳企業有限公司 | O13: TW018135A1 | P13: TW01813500 | Q13: 姿芳科技有限公司 | X13: TW012762A1 | Y13: 大銀幕視聽音響有限公司 | Z13: AV店
... A38: TT230494郭 本威 | B38: 郭本威 | C38: OBS | L38: TW219232A1 | M38: TW21923200 | N38: 宸逸企業社 | O38: TW219252A1 | P38: TW21925200 | Q38: 黃金林企業有限公司 | X38: TW219289A1 | Y38: 鈺陞有限公司 | Z38: 批店
A39: TT230648吳 睿涵 | B39: 吳睿涵 | C39: E-Commerce | L39: TW219252A1 | M39: TW21925200 | N39: 黃金林企業有限公司 | O39: TW219252A1 | P39: TW21925200 | Q39: 黃金林企業有限公司
A40: TT230411林 宜慧 | B40: 林宜慧 | C40: E-Commerce | L40: TW012796A1 | M40: TW01279600 | N40: 泰梭股份有限公司 | O40: TW219256A1 | P40: TW21925600 | Q40: 泰梭企業社
A41: TT230642吳 沛綺 | B41: 吳沛綺 | C41: SCM | L41: TW219256A1 | M41: TW21925600 | N41: 泰梭企業社 | O41: TW219256A1 | P41: TW21925600 | Q41: 泰梭企業社
A42: TT230686胡 智偉 | B42: 胡智偉 | C42: 台中營銷處 | L42: TW014840A1 | M42: TW01484000 | N42: 益昇商行 | O42: TW219258A1 | P42: TW21925800 | Q42: 倉泉有限公司
A43: TT230790莊 淳然 | B43: 莊淳然 | C43: ID Part | L43: TW219258A1 | M43: TW21925800 | N43: 倉泉有限公司 | O43: TW219258A1 | P43: TW21925800 | Q43: 倉泉有限公司
A44: TT001518羅 時景 | B44: 羅時景 | C44: ETC | L44: TW219259A1 | M44: TW21925900 | N44: 尚合雅有限公司 | O44: TW219259A1 | P44: TW21925900 | Q44: 尚合雅有限公司
A45: TT230808廖 婉婷 | B45: 廖婉婷 | C45: B2B2C | L45: TW219473A1 | M45: TW21947300 | N45: 金合雅有限公司 | O45: TW219259A1 | P45: TW21925900 | Q45: 尚合雅有限公司
A46: TT230838陳 良緒 | B46: 陳良緒 | C46: Admin | L46: TW219284A1 | M46: TW21928400 | N46: 佳美百事購有限公司 | O46: TW219284A1 | P46: TW21928400 | Q46: 佳美百事購有限公司
A47: TT230878陳 士騏 | B47: 陳士騏 | C47: E-Commerce | L47: TW219189A1 | M47: TW21918900 | N47: 佳美電器行 | O47: TW219284A1 | P47: TW21928400 | Q47: 佳美百事購有限公司
A48: TT001406陳 俊宏 | B48: 陳俊宏 | C48: 百貨 | L48: TW219314A1 | M48: TW21931400 | N48: 翰鉅有限公司 | O48: TW219285A1 | P48: TW21928500 | Q48: 豪順興業有限公司
A49: TT230545吳 章瑋 | B49: 吳章瑋 | C49: AC Team | L49: TW219285A1 | M49: TW21928500 | N49: 豪順興業有限公司 | O49: TW219285A1 | P49: TW21928500 | Q49: 豪順興業有限公司
L50: TW009380A1 | M50: TW00938000 | N50: 世英電業行 | O50: TW219287A1 | P50: TW21928700 | Q50: 佳新電業有限公司
L51: TW219287A1 | M51: TW21928700 | N51: 佳新電業有限公司 | O51: TW219287A1 | P51: TW21928700 | Q51: 佳新電業有限公司
L52: TW219289A1 | M52: TW21928900 | N52: 鈺陞有限公司 | O52: TW219289A1 | P52: TW21928900 | Q52: 鈺陞有限公司
L53: TW010118A1 | M53: TW01011800 | N53: 格愛陞有限公司 | O53: TW219289A1 | P53: TW21928900 | Q53: 鈺陞有限公司
L54: TW219305A1 | M54: TW21930500 | N54: 銘鎧電器行 | O54: TW219305A1 | P54: TW21930500 | Q54: 銘鎧電器行
L55: TW010950A1 | M55: TW01095000 | N55: 強尼電器百貨大批發 | O55: TW219320A1 | P55: TW21932000 | Q55: 強尼電器行
L56: TW219320A1 | M56: TW21932000 | N56: 強尼電器行 | O56: TW219320A1 | P56: TW21932000 | Q56: 強尼電器行
L57: TW219326A1 | M57: TW21932600 | N57: 上加實業有限公司 | O57: TW219326A1 | P57: TW21932600 | Q57: 上加實業有限公司
L58: TW013768A1 | M58: TW01376800 | N58: 上加電器有限公司 | O58: TW219326A1 | P58: TW21932600 | Q58: 上加實業有限公司
L59: TW014724A1 | M59: TW01472400 | N59: 九瑜電氣行 | O59: TW219336A1 | P59: TW21933600 | Q59: 立宏空調科技有限公司
L60: TW219336A1 | M60: TW21933600 | N60: 立宏空調科技有限公司 | O60: TW219336A1 | P60: TW21933600 | Q60: 立宏空調科技有限公司
L61: TW014621A1 | M61: TW01462100 | N61: 南霸天電器有限公司 | O61: TW219617A1 | P61: TW21945500 | Q61: 九三電器有限公司
... L68: TW017154A1 | M68: TW01715400 | N68: 特家麗企業有限公司鹿港分公司 | O68: TW219581A1 | P68: TW21958100 | Q68: 特家麗家電生活館有限公司
